Oops! Sol just crashed;
Here's this crash log!

Quick Fix for users: N/A (Not Available)

Cause: None
Context: unhashable type: 'dict'
Exceptions (if available): None
Error Type: NameError
Error: name 'prine' is not defined. Did you mean: 'print'?

FrameSummary #1:
  | Filename: E:\Code\Sol\Sol 0.211\Sol.py
  | Line: solcons.draw(event)
  | Line #: 313
  | Data: None

FrameSummary #2:
  | Filename: E:\Code\Sol\Sol 0.211\classes\overlay\console.py
  | Line: prine
  | Line #: 63
  | Data: None

Traceback dictionary: {'max_group_width': 15, 'max_group_depth': 10, 'stack': [<FrameSummary file E:\Code\Sol\Sol 0.211\Sol.py, line 313 in <module>>, <FrameSummary file E:\Code\Sol\Sol 0.211\classes\overlay\console.py, line 63 in draw>], 'exc_type': <class 'NameError'>, '_str': "name 'prine' is not defined. Did you mean: 'print'?", '__notes__': None, '__suppress_context__': False, '__cause__': None, '__context__': <traceback.TracebackException object at 0x000001ABED777290>, 'exceptions': None}


Please send this file to the developers of Sol at https://github.com/Za9-118/Sol/issues.
Your feedback is important to me!